Workbook

Sheet PROBLEM
A1: You are working with the National Statistical Office which is equipped to release inflation numbers in India. As an analyst, you are provided with CPl data and are equipped to find out insights from the data. Your senior wants you to find key trends and deep dive into the data to answer the following questions - 1. Based on the latest month's data, identify the contribution of different broader categories (food, energy, transportation, education, etc.) towards the CPI basket. Broader categories (buckets) can be created by combining similar categories into one bucket; Ex.: Meals, Beverages, Cereals, can be clubbed to create "Food" category, etc. • Which broader category has the highest contribution towards towards CPI calculation • Contribution is calculated by evaluating the underlying index values for broader category and should add to 100% when contribution from different broader categories are added. 2. A trend of Y-o-Y increase in CPI (rural + urban) inflation starting 2017 for the entire basket of products combined. • Create a graph depicting the growth rate Y-o-Y and identify the year with highest inflation rate • Highlight the reason why the year has the highest inflation (based on research). Prev 3. With India's retail inflation reaching a 3-month high of 5.55% in November 2023, largely due to a sharp rise in food prices. Analyze the following for 12 months ending May'23 • Investigate trends in the prices of broader food bucket category and evaluate month-on-month changes. Highlight month with highest and lowest food inflation • Identify the absolute changes in inflation over the same 12 months period and identify the biggest individual category contributor (only within broader food category) towards inflation 4. Investigate how the onset and progression of the COVID-19 pandemic affected inflation rates in India. Analyze the Impact of key pandemic milestone (first lockdown) on the CPI inflation %, specially focus on categories like healthcare, food, and essential services. Hint: You can consider Mar'20 as the onset of covid, and can compare the inflation trend before and after Mar'20 to see if there is a change in inflation % before and after. 5. Investigate how major global economic events (like imported crude oil price fluctuations) have influenced India's inflation. This can include an analysis of imported goods and their price trends. • For the purpose of this analysis, focus only on the imported oil price fluctuations for years 2021 to 2023 (Month-on-month • Identify trends in oil price change with change in inflation prices of all the categories and identify category whose inflation prices strongly changes with fluctuations in imported oil price (Hint: you can use =correl function)

Sheet Formula Used
A1: Problems | B1: ACTION/FORMULA
A2: To find the count of missing values | B2: COUNTBLANK, [COUNTIF(RANGE,"NA") + COUNTIF(RANGE,"-")]
A3: To Fill the missing values cells | B3: AVERAGE(PREVIOUS TWO VALUES OF SAME SECTOR)
A4: To Unpivot the data | B4: USED POWER QUERY>TRANFORM DATA>UNPIVOT OTHER COLUMNS
A5: To Merge the queries | B5: USED POWER QUERY>MERGE QUERIES
A6: CPI for a year | B6: AVERAGE VALUES OF ALL CATEGORIES FOR THE SAME YEAR
A7: To find the Inflation | B7: (CURRENT MONTH/YEAR-PREVIOUS MONTH/YEAR)/PREVIOUS MONTH/YEAR * 100
A8: To find the Correlation between Crude Oil & Different Categories | B8: CORREL(RANGE OF CRUIDE OIL PRICE,RANGE OF RESPECTIVE CATEGORY)

Sheet All_India_Index_Upto_April23 (1
A1: =COUNTIF(A2:A373, "NA") + COUNTIF(A2:A373, "-") -> 0 | B1: =COUNTIF(B2:B373, "NA") + COUNTIF(B2:B373, "-") -> 0 | C1: =COUNTIF(C2:C373, "NA") + COUNTIF(C2:C373, "-") -> 0 | D1: =COUNTIF(D2:D373, "NA") + COUNTIF(D2:D373, "-") -> 3 | E1: =COUNTIF(E2:E373, "NA") + COUNTIF(E2:E373, "-") -> 6 | F1: =COUNTIF(F2:F373, "NA") + COUNTIF(F2:F373, "-") -> 3 | G1: =COUNTIF(G2:G373, "NA") + COUNTIF(G2:G373, "-") -> 3 | H1: =COUNTIF(H2:H373, "NA") + COUNTIF(H2:H373, "-") -> 3 | ... AD1: =COUNTIF(AD2:AD373, "NA") + COUNTIF(AD2:AD373, "-") -> 6
A2: Sector | B2: Year | C2: Month | D2: Cereals and products | E2: Meat and fish | F2: Egg | G2: Milk and products | H2: Oils and fats | I2: Fruits | J2: Vegetables | K2: Pulses and products | L2: Sugar and Confectionery | M2: Spices | N2: Non-alcoholic beverages | O2: Prepared meals, snacks, sweets etc. | P2: Food and beverages | Q2: Pan, tobacco and intoxicants | R2: Clothing | S2: Footwear | T2: Clothing and footwear | U2: Housing | V2: Fuel and light | W2: Household goods and services | X2: Health | Y2: Transport and communication | Z2: Recreation and amusement | AA2: Education | AB2: Personal care and effects | AC2: Miscellaneous | AD2: General index
A3: Rural | B3: 2013 | C3: January | D3: 107.5 | E3: 106.3 | F3: 108.1 | G3: 104.9 | H3: 106.1 | I3: 103.9 | J3: 101.9 | K3: 106.1 | L3: 106.8 | M3: 103.1 | N3: 104.8 | O3: 106.7 | P3: 105.5 | Q3: 105.1 | R3: 106.5 | S3: 105.8 | T3: 106.4 | U3: NA | V3: 105.5 | W3: 104.8 | X3: 104 | Y3: 103.3 | Z3: 103.4 | AA3: 103.8 | AB3: 104.7 | AC3: 104 | AD3: 105.1
A4: Urban | B4: 2013 | C4: January | D4: 110.5 | E4: 109.1 | F4: 113 | G4: 103.6 | H4: 103.4 | I4: 102.3 | J4: 102.9 | K4: 105.8 | L4: 105.1 | M4: 101.8 | N4: 105.1 | O4: 107.9 | P4: 105.9 | Q4: 105.2 | R4: 105.9 | S4: 105 | T4: 105.8 | U4: 100.3 | V4: 105.4 | W4: 104.8 | X4: 104.1 | Y4: 103.2 | Z4: 102.9 | AA4: 103.5 | AB4: 104.3 | AC4: 103.7 | AD4: 104
A5: Rural+Urban | B5: 2013 | C5: January | D5: 108.4 | E5: 107.3 | F5: 110 | G5: 104.4 | H5: 105.1 | I5: 103.2 | J5: 102.2 | K5: 106 | L5: 106.2 | M5: 102.7 | N5: 104.9 | O5: 107.3 | P5: 105.6 | Q5: 105.1 | R5: 106.3 | S5: 105.5 | T5: 106.2 | U5: 100.3 | V5: 105.5 | W5: 104.8 | X5: 104 | Y5: 103.2 | Z5: 103.1 | AA5: 103.6 | AB5: 104.5 | AC5: 103.9 | AD5: 104.6
A6: Rural | B6: 2013 | C6: February | D6: 109.2 | E6: 108.7 | F6: 110.2 | G6: 105.4 | H6: 106.7 | I6: 104 | J6: 102.4 | K6: 105.9 | L6: 105.7 | M6: 103.1 | N6: 105.1 | O6: 107.7 | P6: 106.3 | Q6: 105.6 | R6: 107.1 | S6: 106.3 | T6: 107 | U6: NA | V6: 106.2 | W6: 105.2 | X6: 104.4 | Y6: 103.9 | Z6: 104 | AA6: 104.1 | AB6: 104.6 | AC6: 104.4 | AD6: 105.8
A7: Urban | B7: 2013 | C7: February | D7: 112.9 | E7: 112.9 | F7: 116.9 | G7: 104 | H7: 103.5 | I7: 103.1 | J7: 104.9 | K7: 104.1 | L7: 103.8 | M7: 102.3 | N7: 106 | O7: 109 | P7: 107.2 | Q7: 106 | R7: 106.6 | S7: 105.5 | T7: 106.4 | U7: 100.4 | V7: 105.7 | W7: 105.2 | X7: 104.7 | Y7: 104.4 | Z7: 103.3 | AA7: 103.7 | AB7: 104.3 | AC7: 104.3 | AD7: 104.7
A8: Rural+Urban | B8: 2013 | C8: February | D8: 110.4 | E8: 110.2 | F8: 112.8 | G8: 104.9 | H8: 105.5 | I8: 103.6 | J8: 103.2 | K8: 105.3 | L8: 105.1 | M8: 102.8 | N8: 105.5 | O8: 108.3 | P8: 106.6 | Q8: 105.7 | R8: 106.9 | S8: 106 | T8: 106.8 | U8: 100.4 | V8: 106 | W8: 105.2 | X8: 104.5 | Y8: 104.2 | Z8: 103.6 | AA8: 103.9 | AB8: 104.5 | AC8: 104.4 | AD8: 105.3
A9: Rural | B9: 2013 | C9: March | D9: 110.2 | E9: 108.8 | F9: 109.9 | G9: 105.6 | H9: 106.2 | I9: 105.7 | J9: 101.4 | K9: 105.7 | L9: 105 | M9: 103.3 | N9: 105.6 | O9: 108.2 | P9: 106.6 | Q9: 106.5 | R9: 107.6 | S9: 106.8 | T9: 107.5 | U9: NA | V9: 106.1 | W9: 105.6 | X9: 104.7 | Y9: 104.6 | Z9: 104 | AA9: 104.3 | AB9: 104.3 | AC9: 104.6 | AD9: 106
A10: Urban | B10: 2013 | C10: March | D10: 113.9 | E10: 111.4 | F10: 113.2 | G10: 104.3 | H10: 102.7 | I10: 104.9 | J10: 103.8 | K10: 103.5 | L10: 102.6 | M10: 102.4 | N10: 107 | O10: 109.8 | P10: 107.3 | Q10: 106.8 | R10: 107.2 | S10: 106 | T10: 107 | U10: 100.4 | V10: 106 | W10: 105.7 | X10: 105.2 | Y10: 105.5 | Z10: 103.5 | AA10: 103.8 | AB10: 104.2 | AC10: 104.9 | AD10: 105
A11: Rural+Urban | B11: 2013 | C11: March | D11: 111.4 | E11: 109.7 | F11: 111.2 | G11: 105.1 | H11: 104.9 | I11: 105.3 | J11: 102.2 | K11: 105 | L11: 104.2 | M11: 103 | N11: 106.2 | O11: 108.9 | P11: 106.9 | Q11: 106.6 | R11: 107.4 | S11: 106.5 | T11: 107.3 | U11: 100.4 | V11: 106.1 | W11: 105.6 | X11: 104.9 | Y11: 105.1 | Z11: 103.7 | AA11: 104 | AB11: 104.3 | AC11: 104.7 | AD11: 105.5
A12: Rural | B12: 2013 | C12: April | D12: 110.2 | E12: 109.5 | F12: 106.9 | G12: 106.3 | H12: 105.7 | I12: 108.3 | J12: 103.4 | K12: 105.7 | L12: 104.2 | M12: 103.2 | N12: 106.5 | O12: 108.8 | P12: 107.1 | Q12: 107.1 | R12: 108.1 | S12: 107.4 | T12: 108 | U12: NA | V12: 106.5 | W12: 106.1 | X12: 105.1 | Y12: 104.4 | Z12: 104.5 | AA12: 104.8 | AB12: 102.7 | AC12: 104.6 | AD12: 106.4
A13: Urban | B13: 2013 | C13: April | D13: 114.6 | E13: 113.4 | F13: 106 | G13: 104.7 | H13: 102.1 | I13: 109.5 | J13: 109.7 | K13: 104.6 | L13: 102 | M13: 103.5 | N13: 108.2 | O13: 110.6 | P13: 108.8 | Q13: 108.5 | R13: 107.9 | S13: 106.4 | T13: 107.7 | U13: 100.5 | V13: 106.4 | W13: 106.5 | X13: 105.7 | Y13: 105 | Z13: 104 | AA13: 105.2 | AB13: 103.2 | AC13: 105.1 | AD13: 105.7
A14: Rural+Urban | B14: 2013 | C14: April | D14: 111.6 | E14: 110.9 | F14: 106.6 | G14: 105.7 | H14: 104.4 | I14: 108.9 | J14: 105.5 | K14: 105.3 | L14: 103.5 | M14: 103.3 | N14: 107.2 | O14: 109.6 | P14: 107.7 | Q14: 107.5 | R14: 108 | S14: 107 | T14: 107.9 | U14: 100.5 | V14: 106.5 | W14: 106.3 | X14: 105.3 | Y14: 104.7 | Z14: 104.2 | AA14: 105 | AB14: 102.9 | AC14: 104.8 | AD14: 106.1
A15: Rural | B15: 2013 | C15: May | D15: 110.9 | E15: 109.8 | F15: 105.9 | G15: 107.5 | H15: 105.3 | I15: 108.1 | J15: 107.3 | K15: 106.1 | L15: 103.7 | M15: 104 | N15: 107.4 | O15: 109.9 | P15: 108.1 | Q15: 108.1 | R15: 108.8 | S15: 107.9 | T15: 108.6 | U15: NA | V15: 107.5 | W15: 106.8 | X15: 105.7 | Y15: 104.1 | Z15: 105 | AA15: 105.5 | AB15: 102.1 | AC15: 104.8 | AD15: 107.2
A16: Urban | B16: 2013 | C16: May | D16: 115.4 | E16: 114.2 | F16: 102.7 | G16: 105.5 | H16: 101.5 | I16: 110.6 | J16: 123.7 | K16: 105.2 | L16: 101.9 | M16: 105 | N16: 109.1 | O16: 111.3 | P16: 111.1 | Q16: 109.8 | R16: 108.5 | S16: 106.7 | T16: 108.3 | U16: 100.5 | V16: 107.2 | W16: 107.1 | X16: 106.2 | Y16: 103.9 | Z16: 104.6 | AA16: 105.7 | AB16: 102.6 | AC16: 104.9 | AD16: 106.6
A17: Rural+Urban | B17: 2013 | C17: May | D17: 112.3 | E17: 111.3 | F17: 104.7 | G17: 106.8 | H17: 103.9 | I17: 109.3 | J17: 112.9 | K17: 105.8 | L17: 103.1 | M17: 104.3 | N17: 108.1 | O17: 110.5 | P17: 109.2 | Q17: 108.6 | R17: 108.7 | S17: 107.4 | T17: 108.5 | U17: 100.5 | V17: 107.4 | W17: 106.9 | X17: 105.9 | Y17: 104 | Z17: 104.8 | AA17: 105.6 | AB17: 102.3 | AC17: 104.8 | AD17: 106.9
A18: Rural | B18: 2013 | C18: June | D18: 112.3 | E18: 112.1 | F18: 108.1 | G18: 108.3 | H18: 105.9 | I18: 109.2 | J18: 118 | K18: 106.8 | L18: 104.1 | M18: 105.4 | N18: 108.2 | O18: 111 | P18: 110.6 | Q18: 109 | R18: 109.7 | S18: 108.8 | T18: 109.5 | U18: NA | V18: 108.5 | W18: 107.5 | X18: 106.3 | Y18: 105 | Z18: 105.6 | AA18: 106.5 | AB18: 102.5 | AC18: 105.5 | AD18: 108.9
A19: Urban | B19: 2013 | C19: June | D19: 117 | E19: 120.1 | F19: 112.5 | G19: 107.3 | H19: 101.3 | I19: 112.4 | J19: 143.6 | K19: 105.4 | L19: 101.4 | M19: 106.4 | N19: 110 | O19: 112.2 | P19: 115 | Q19: 110.9 | R19: 109.2 | S19: 107.2 | T19: 108.9 | U19: 106.6 | V19: 108 | W19: 107.7 | X19: 106.5 | Y19: 105.2 | Z19: 105.2 | AA19: 108.1 | AB19: 103.3 | AC19: 106.1 | AD19: 109.7
A20: Rural+Urban | B20: 2013 | C20: June | D20: 113.8 | E20: 114.9 | F20: 109.8 | G20: 107.9 | H20: 104.2 | I20: 110.7 | J20: 126.7 | K20: 106.3 | L20: 103.2 | M20: 105.7 | N20: 109 | O20: 111.6 | P20: 112.2 | Q20: 109.5 | R20: 109.5 | S20: 108.1 | T20: 109.3 | U20: 106.6 | V20: 108.3 | W20: 107.6 | X20: 106.4 | Y20: 105.1 | Z20: 105.4 | AA20: 107.4 | AB20: 102.8 | AC20: 105.8 | AD20: 109.3
A21: Rural | B21: 2013 | C21: July | D21: 113.4 | E21: 114.9 | F21: 110.5 | G21: 109.3 | H21: 106.2 | I21: 110.3 | J21: 129.2 | K21: 107.1 | L21: 104.3 | M21: 106.4 | N21: 109.1 | O21: 112.1 | P21: 113.1 | Q21: 109.8 | R21: 110.5 | S21: 109.5 | T21: 110.3 | U21: NA | V21: 109.5 | W21: 108.3 | X21: 106.9 | Y21: 106.8 | Z21: 106.4 | AA21: 107.8 | AB21: 102.5 | AC21: 106.5 | AD21: 110.7
A22: Urban | B22: 2013 | C22: July | D22: 117.8 | E22: 119.2 | F22: 114 | G22: 108.3 | H22: 101.1 | I22: 113.2 | J22: 160.9 | K22: 105.1 | L22: 101.3 | M22: 107.5 | N22: 110.4 | O22: 113.1 | P22: 117.5 | Q22: 111.7 | R22: 109.8 | S22: 107.8 | T22: 109.5 | U22: 107.7 | V22: 108.6 | W22: 108.1 | X22: 107.1 | Y22: 107.3 | Z22: 105.9 | AA22: 110.1 | AB22: 103.2 | AC22: 107.3 | AD22: 111.4
A23: Rural+Urban | B23: 2013 | C23: July | D23: 114.8 | E23: 116.4 | F23: 111.9 | G23: 108.9 | H23: 104.3 | I23: 111.7 | J23: 140 | K23: 106.4 | L23: 103.3 | M23: 106.8 | N23: 109.6 | O23: 112.6 | P23: 114.7 | Q23: 110.3 | R23: 110.2 | S23: 108.8 | T23: 110 | U23: 107.7 | V23: 109.2 | W23: 108.2 | X23: 107 | Y23: 107.1 | Z23: 106.1 | AA23: 109.1 | AB23: 102.8 | AC23: 106.9 | AD23: 111
A24: Rural | B24: 2013 | C24: August | D24: 114.3 | E24: 115.4 | F24: 111.1 | G24: 110 | H24: 106.4 | I24: 110.8 | J24: 138.9 | K24: 107.4 | L24: 104.1 | M24: 106.9 | N24: 109.7 | O24: 112.6 | P24: 114.9 | Q24: 110.7 | R24: 111.3 | S24: 110.2 | T24: 111.1 | U24: NA | V24: 109.9 | W24: 108.7 | X24: 107.5 | Y24: 107.8 | Z24: 106.8 | AA24: 108.7 | AB24: 105 | AC24: 107.5 | AD24: 112.1
A25: Urban | B25: 2013 | C25: August | D25: 118.3 | E25: 120.4 | F25: 112.7 | G25: 108.9 | H25: 101.1 | I25: 108.7 | J25: 177 | K25: 104.7 | L25: 101 | M25: 108.5 | N25: 110.9 | O25: 114.3 | P25: 119.6 | Q25: 112.4 | R25: 110.6 | S25: 108.3 | T25: 110.2 | U25: 108.9 | V25: 109.3 | W25: 108.7 | X25: 107.6 | Y25: 108.1 | Z25: 106.5 | AA25: 110.8 | AB25: 106 | AC25: 108.3 | AD25: 112.7
A26: Rural+Urban | B26: 2013 | C26: August | D26: 115.6 | E26: 117.2 | F26: 111.7 | G26: 109.6 | H26: 104.5 | I26: 109.8 | J26: 151.8 | K26: 106.5 | L26: 103.1 | M26: 107.4 | N26: 110.2 | O26: 113.4 | P26: 116.6 | Q26: 111.2 | R26: 111 | S26: 109.4 | T26: 110.7 | U26: 108.9 | V26: 109.7 | W26: 108.7 | X26: 107.5 | Y26: 108 | Z26: 106.6 | AA26: 109.9 | AB26: 105.4 | AC26: 107.9 | AD26: 112.4
A27: Rural | B27: 2013 | C27: September | D27: 115.4 | E27: 115.7 | F27: 111.7 | G27: 111 | H27: 107.4 | I27: 110.9 | J27: 154 | K27: 108.1 | L27: 104.2 | M27: 107.9 | N27: 110.4 | O27: 114 | P27: 117.8 | Q27: 111.7 | R27: 112.7 | S27: 111.4 | T27: 112.5 | U27: NA | V27: 111.1 | W27: 109.6 | X27: 108.3 | Y27: 109.3 | Z27: 107.7 | AA27: 109.8 | AB27: 106.7 | AC27: 108.7 | AD27: 114.2
A28: Urban | B28: 2013 | C28: September | D28: 118.6 | E28: 119.1 | F28: 113.2 | G28: 109.6 | H28: 101.7 | I28: 103.2 | J28: 174.3 | K28: 105.1 | L28: 100.8 | M28: 109.1 | N28: 111.1 | O28: 115.4 | P28: 119.2 | Q28: 112.9 | R28: 111.4 | S28: 109 | T28: 111.1 | U28: 109.7 | V28: 109.5 | W28: 109.6 | X28: 107.9 | Y28: 110.4 | Z28: 107.4 | AA28: 111.2 | AB28: 106.9 | AC28: 109.4 | AD28: 113.2
A29: Rural+Urban | B29: 2013 | C29: September | D29: 116.4 | E29: 116.9 | F29: 112.3 | G29: 110.5 | H29: 105.3 | I29: 107.3 | J29: 160.9 | K29: 107.1 | L29: 103.1 | M29: 108.3 | N29: 110.7 | O29: 114.6 | P29: 118.3 | Q29: 112 | R29: 112.2 | S29: 110.4 | T29: 111.9 | U29: 109.7 | V29: 110.5 | W29: 109.6 | X29: 108.1 | Y29: 109.9 | Z29: 107.5 | AA29: 110.6 | AB29: 106.8 | AC29: 109 | AD29: 113.7
A30: Rural | B30: 2013 | C30: October | D30: 116.3 | E30: 115.4 | F30: 112.6 | G30: 111.7 | H30: 107.7 | I30: 113.2 | J30: 164.9 | K30: 108.3 | L30: 103.9 | M30: 108.2 | N30: 111.1 | O30: 114.9 | P30: 119.8 | Q30: 112.2 | R30: 113.6 | S30: 112.3 | T30: 113.4 | U30: NA | V30: 111.6 | W30: 110.4 | X30: 108.9 | Y30: 109.3 | Z30: 108.3 | AA30: 110.2 | AB30: 107.5 | AC30: 109.1 | AD30: 115.5
A31: Urban | B31: 2013 | C31: October | D31: 118.9 | E31: 118.1 | F31: 114.5 | G31: 110.4 | H31: 102.3 | I31: 106.2 | J31: 183.5 | K31: 105.3 | L31: 100.2 | M31: 109.6 | N31: 111.4 | O31: 116 | P31: 120.8 | Q31: 113.5 | R31: 112.5 | S31: 109.7 | T31: 112 | U31: 110.5 | V31: 109.7 | W31: 110.2 | X31: 108.2 | Y31: 109.7 | Z31: 108 | AA31: 111.3 | AB31: 107.3 | AC31: 109.4 | AD31: 114
A32: Rural+Urban | B32: 2013 | C32: October | D32: 117.1 | E32: 116.3 | F32: 113.3 | G32: 111.2 | H32: 105.7 | I32: 109.9 | J32: 171.2 | K32: 107.3 | L32: 102.7 | M32: 108.7 | N32: 111.2 | O32: 115.4 | P32: 120.2 | Q32: 112.5 | R32: 113.2 | S32: 111.2 | T32: 112.8 | U32: 110.5 | V32: 110.9 | W32: 110.3 | X32: 108.6 | Y32: 109.5 | Z32: 108.1 | AA32: 110.8 | AB32: 107.4 | AC32: 109.2 | AD32: 114.8
A33: Rural | B33: 2013 | C33: November | D33: 117.3 | E33: 114.9 | F33: 116.2 | G33: 112.8 | H33: 108.9 | I33: 116.6 | J33: 178.1 | K33: 109.1 | L33: 103.6 | M33: 109 | N33: 111.8 | O33: 116 | P33: 122.5 | Q33: 112.8 | R33: 114.6 | S33: 113.1 | T33: 114.4 | U33: NA | V33: 112.6 | W33: 111.3 | X33: 109.7 | Y33: 109.6 | Z33: 108.7 | AA33: 111 | AB33: 108.2 | AC33: 109.8 | AD33: 117.4
A34: Urban | B34: 2013 | C34: November | D34: 119.8 | E34: 116.3 | F34: 122.6 | G34: 112 | H34: 103.2 | I34: 110 | J34: 192.8 | K34: 106.3 | L34: 99.5 | M34: 110.3 | N34: 111.8 | O34: 117.1 | P34: 122.9 | Q34: 114.1 | R34: 113.5 | S34: 110.3 | T34: 113 | U34: 111.1 | V34: 110 | W34: 110.9 | X34: 108.6 | Y34: 109.5 | Z34: 108.5 | AA34: 111.3 | AB34: 107.9 | AC34: 109.6 | AD34: 115
A35: Rural+Urban | B35: 2013 | C35: November | D35: 118.1 | E35: 115.4 | F35: 118.7 | G35: 112.5 | H35: 106.8 | I35: 113.5 | J35: 183.1 | K35: 108.2 | L35: 102.2 | M35: 109.4 | N35: 111.8 | O35: 116.5 | P35: 122.6 | Q35: 113.1 | R35: 114.2 | S35: 111.9 | T35: 113.8 | U35: 111.1 | V35: 111.6 | W35: 111.1 | X35: 109.3 | Y35: 109.5 | Z35: 108.6 | AA35: 111.2 | AB35: 108.1 | AC35: 109.7 | AD35: 116.3
A36: Rural | B36: 2013 | C36: December | D36: 118.4 | E36: 115.9 | F36: 120.4 | G36: 113.8 | H36: 109.5 | I36: 115.5 | J36: 145.7 | K36: 109.5 | L36: 102.9 | M36: 109.8 | N36: 112.1 | O36: 116.8 | P36: 118.7 | Q36: 113.6 | R36: 115.8 | S36: 114 | T36: 115.5 | U36: NA | V36: 112.8 | W36: 112.1 | X36: 110.1 | Y36: 109.9 | Z36: 109.2 | AA36: 111.6 | AB36: 108.1 | AC36: 110.1 | AD36: 115.5
A37: Urban | B37: 2013 | C37: December | D37: 120.5 | E37: 118.1 | F37: 128.5 | G37: 112.8 | H37: 103.4 | I37: 110.7 | J37: 144.8 | K37: 107.1 | L37: 98.6 | M37: 111.9 | N37: 112.1 | O37: 118.1 | P37: 117.8 | Q37: 115 | R37: 114.2 | S37: 110.9 | T37: 113.7 | U37: 110.7 | V37: 110.4 | W37: 111.3 | X37: 109 | Y37: 109.7 | Z37: 108.9 | AA37: 111.4 | AB37: 107.7 | AC37: 109.8 | AD37: 113.3
A38: Rural+Urban | B38: 2013 | C38: December | D38: 119.1 | E38: 116.7 | F38: 123.5 | G38: 113.4 | H38: 107.3 | I38: 113.3 | J38: 145.4 | K38: 108.7 | L38: 101.5 | M38: 110.5 | N38: 112.1 | O38: 117.4 | P38: 118.4 | Q38: 114 | R38: 115.2 | S38: 112.7 | T38: 114.8 | U38: 110.7 | V38: 111.9 | W38: 111.7 | X38: 109.7 | Y38: 109.8 | Z38: 109 | AA38: 111.5 | AB38: 107.9 | AC38: 110 | AD38: 114.5
A39: Rural | B39: 2014 | C39: January | D39: 118.9 | E39: 117.1 | F39: 120.5 | G39: 114.4 | H39: 109 | I39: 115.5 | J39: 123.9 | K39: 109.6 | L39: 101.8 | M39: 110.2 | N39: 112.4 | O39: 117.3 | P39: 116 | Q39: 114 | R39: 116.5 | S39: 114.5 | T39: 116.2 | U39: NA | V39: 113 | W39: 112.6 | X39: 110.6 | Y39: 110.5 | Z39: 109.6 | AA39: 111.8 | AB39: 108.3 | AC39: 110.6 | AD39: 114.2
A40: Urban | B40: 2014 | C40: January | D40: 121.2 | E40: 122 | F40: 129.9 | G40: 113.6 | H40: 102.9 | I40: 112.1 | J40: 118.9 | K40: 107.5 | L40: 96.9 | M40: 112.7 | N40: 112.1 | O40: 119 | P40: 115.5 | Q40: 115.7 | R40: 114.8 | S40: 111.3 | T40: 114.3 | U40: 111.6 | V40: 111 | W40: 111.9 | X40: 109.7 | Y40: 110.8 | Z40: 109.8 | AA40: 111.5 | AB40: 108 | AC40: 110.5 | AD40: 112.9
...

Sheet Cleaning
A1: =COUNTIF(Table2[Sector], "NA") -> 0 | B1: =COUNTIF(Table2[Sector], "NA") -> 0 | C1: =COUNTIF(Table2[Sector], "NA") -> 0 | D1: =COUNTIF(Table2[Sector], "NA") -> 0 | E1: =COUNTIF(Table2[Sector], "NA") -> 0 | F1: =COUNTIF(Table2[Sector], "NA") -> 0 | G1: =COUNTIF(Table2[Sector], "NA") -> 0 | H1: =COUNTIF(Table2[Sector], "NA") -> 0 | ... AB1: =COUNTIF(Table2[Sector], "NA") -> 0
A2: Sector | B2: Year | C2: Month | D2: Cereals and products | E2: Meat and fish | F2: Egg | G2: Milk and products | H2: Oils and fats | I2: Fruits | J2: Vegetables | K2: Pulses and products | L2: Sugar and Confectionery | M2: Spices | N2: Nonalcoholic beverages | O2: Prepared meals, scks, sweets etc. | P2: Pan, tobacco and intoxicants | Q2: Clothing | R2: Footwear | S2: Housing | T2: Fuel and light | U2: Household goods and services | V2: Health | W2: Transport and communication | X2: Recreation and amusement | Y2: Education | Z2: Persol care and effects | AA2: Miscellaneous | AB2: General index
A3: Rural | B3: 2013 | C3: January | D3: 107.5 | E3: 106.3 | F3: 108.1 | G3: 104.9 | H3: 106.1 | I3: 103.9 | J3: 101.9 | K3: 106.1 | L3: 106.8 | M3: 103.1 | N3: 104.8 | O3: 106.7 | P3: 105.1 | Q3: 106.5 | R3: 105.8 | S3: 0 | T3: 105.5 | U3: 104.8 | V3: 104 | W3: 103.3 | X3: 103.4 | Y3: 103.8 | Z3: 104.7 | AA3: 104 | AB3: 105.1
A4: Rural | B4: 2013 | C4: February | D4: 109.2 | E4: 108.7 | F4: 110.2 | G4: 105.4 | H4: 106.7 | I4: 104 | J4: 102.4 | K4: 105.9 | L4: 105.7 | M4: 103.1 | N4: 105.1 | O4: 107.7 | P4: 105.6 | Q4: 107.1 | R4: 106.3 | S4: =AVERAGE(S3,S2) -> 0 | T4: 106.2 | U4: 105.2 | V4: 104.4 | W4: 103.9 | X4: 104 | Y4: 104.1 | Z4: 104.6 | AA4: 104.4 | AB4: 105.8
A5: Rural | B5: 2013 | C5: March | D5: 110.2 | E5: 108.8 | F5: 109.9 | G5: 105.6 | H5: 106.2 | I5: 105.7 | J5: 101.4 | K5: 105.7 | L5: 105 | M5: 103.3 | N5: 105.6 | O5: 108.2 | P5: 106.5 | Q5: 107.6 | R5: 106.8 | S5: =AVERAGE(S4,S3) -> 0 | T5: 106.1 | U5: 105.6 | V5: 104.7 | W5: 104.6 | X5: 104 | Y5: 104.3 | Z5: 104.3 | AA5: 104.6 | AB5: 106
A6: Rural | B6: 2013 | C6: April | D6: 110.2 | E6: 109.5 | F6: 106.9 | G6: 106.3 | H6: 105.7 | I6: 108.3 | J6: 103.4 | K6: 105.7 | L6: 104.2 | M6: 103.2 | N6: 106.5 | O6: 108.8 | P6: 107.1 | Q6: 108.1 | R6: 107.4 | S6: =AVERAGE(S5,S4) -> 0 | T6: 106.5 | U6: 106.1 | V6: 105.1 | W6: 104.4 | X6: 104.5 | Y6: 104.8 | Z6: 102.7 | AA6: 104.6 | AB6: 106.4
A7: Rural | B7: 2013 | C7: May | D7: 110.9 | E7: 109.8 | F7: 105.9 | G7: 107.5 | H7: 105.3 | I7: 108.1 | J7: 107.3 | K7: 106.1 | L7: 103.7 | M7: 104 | N7: 107.4 | O7: 109.9 | P7: 108.1 | Q7: 108.8 | R7: 107.9 | S7: =AVERAGE(S6,S5) -> 0 | T7: 107.5 | U7: 106.8 | V7: 105.7 | W7: 104.1 | X7: 105 | Y7: 105.5 | Z7: 102.1 | AA7: 104.8 | AB7: 107.2
A8: Rural | B8: 2013 | C8: June | D8: 112.3 | E8: 112.1 | F8: 108.1 | G8: 108.3 | H8: 105.9 | I8: 109.2 | J8: 118 | K8: 106.8 | L8: 104.1 | M8: 105.4 | N8: 108.2 | O8: 111 | P8: 109 | Q8: 109.7 | R8: 108.8 | S8: =AVERAGE(S7,S6) -> 0 | T8: 108.5 | U8: 107.5 | V8: 106.3 | W8: 105 | X8: 105.6 | Y8: 106.5 | Z8: 102.5 | AA8: 105.5 | AB8: 108.9
A9: Rural | B9: 2013 | C9: July | D9: 113.4 | E9: 114.9 | F9: 110.5 | G9: 109.3 | H9: 106.2 | I9: 110.3 | J9: 129.2 | K9: 107.1 | L9: 104.3 | M9: 106.4 | N9: 109.1 | O9: 112.1 | P9: 109.8 | Q9: 110.5 | R9: 109.5 | S9: =AVERAGE(S8,S7) -> 0 | T9: 109.5 | U9: 108.3 | V9: 106.9 | W9: 106.8 | X9: 106.4 | Y9: 107.8 | Z9: 102.5 | AA9: 106.5 | AB9: 110.7
A10: Rural | B10: 2013 | C10: August | D10: 114.3 | E10: 115.4 | F10: 111.1 | G10: 110 | H10: 106.4 | I10: 110.8 | J10: 138.9 | K10: 107.4 | L10: 104.1 | M10: 106.9 | N10: 109.7 | O10: 112.6 | P10: 110.7 | Q10: 111.3 | R10: 110.2 | S10: =AVERAGE(S9,S8) -> 0 | T10: 109.9 | U10: 108.7 | V10: 107.5 | W10: 107.8 | X10: 106.8 | Y10: 108.7 | Z10: 105 | AA10: 107.5 | AB10: 112.1
A11: Rural | B11: 2013 | C11: September | D11: 115.4 | E11: 115.7 | F11: 111.7 | G11: 111 | H11: 107.4 | I11: 110.9 | J11: 154 | K11: 108.1 | L11: 104.2 | M11: 107.9 | N11: 110.4 | O11: 114 | P11: 111.7 | Q11: 112.7 | R11: 111.4 | S11: =AVERAGE(S10,S9) -> 0 | T11: 111.1 | U11: 109.6 | V11: 108.3 | W11: 109.3 | X11: 107.7 | Y11: 109.8 | Z11: 106.7 | AA11: 108.7 | AB11: 114.2
A12: Rural | B12: 2013 | C12: October | D12: 116.3 | E12: 115.4 | F12: 112.6 | G12: 111.7 | H12: 107.7 | I12: 113.2 | J12: 164.9 | K12: 108.3 | L12: 103.9 | M12: 108.2 | N12: 111.1 | O12: 114.9 | P12: 112.2 | Q12: 113.6 | R12: 112.3 | S12: =AVERAGE(S11,S10) -> 0 | T12: 111.6 | U12: 110.4 | V12: 108.9 | W12: 109.3 | X12: 108.3 | Y12: 110.2 | Z12: 107.5 | AA12: 109.1 | AB12: 115.5
A13: Rural | B13: 2013 | C13: November | D13: 117.3 | E13: 114.9 | F13: 116.2 | G13: 112.8 | H13: 108.9 | I13: 116.6 | J13: 178.1 | K13: 109.1 | L13: 103.6 | M13: 109 | N13: 111.8 | O13: 116 | P13: 112.8 | Q13: 114.6 | R13: 113.1 | S13: =AVERAGE(S12,S11) -> 0 | T13: 112.6 | U13: 111.3 | V13: 109.7 | W13: 109.6 | X13: 108.7 | Y13: 111 | Z13: 108.2 | AA13: 109.8 | AB13: 117.4
A14: Rural | B14: 2013 | C14: December | D14: 118.4 | E14: 115.9 | F14: 120.4 | G14: 113.8 | H14: 109.5 | I14: 115.5 | J14: 145.7 | K14: 109.5 | L14: 102.9 | M14: 109.8 | N14: 112.1 | O14: 116.8 | P14: 113.6 | Q14: 115.8 | R14: 114 | S14: =AVERAGE(S13,S12) -> 0 | T14: 112.8 | U14: 112.1 | V14: 110.1 | W14: 109.9 | X14: 109.2 | Y14: 111.6 | Z14: 108.1 | AA14: 110.1 | AB14: 115.5
A15: Rural | B15: 2014 | C15: January | D15: 118.9 | E15: 117.1 | F15: 120.5 | G15: 114.4 | H15: 109 | I15: 115.5 | J15: 123.9 | K15: 109.6 | L15: 101.8 | M15: 110.2 | N15: 112.4 | O15: 117.3 | P15: 114 | Q15: 116.5 | R15: 114.5 | S15: =AVERAGE(S14,S13) -> 0 | T15: 113 | U15: 112.6 | V15: 110.6 | W15: 110.5 | X15: 109.6 | Y15: 111.8 | Z15: 108.3 | AA15: 110.6 | AB15: 114.2
... A88: Rural | B88: 2020 | C88: March | D88: 144.4 | E88: 166.8 | F88: 147.6 | G88: 151.7 | H88: 133.3 | I88: 141.8 | J88: 152.3 | K88: 141.8 | L88: 112.6 | M88: 154 | N88: 140.1 | O88: 160 | P88: 170.5 | Q88: 153.4 | R88: 147.6 | S88: =AVERAGE(S87,S86) -> 0 | T88: 153.4 | U88: 151.5 | V88: 156.7 | W88: 135.8 | X88: 151.2 | Y88: 161.2 | Z88: 145.1 | AA88: 148.6 | AB88: 149.8
A89: Rural | B89: 2020 | C89: April | D89: 147.2 | E89: =AVERAGE(E88,E87) -> 167.15 | F89: 146.9 | G89: 155.6 | H89: 137.1 | I89: 147.3 | J89: 162.7 | K89: 150.2 | L89: 119.8 | M89: 158.7 | N89: 139.2 | O89: =AVERAGE(O88,O87) -> 159.6 | P89: =AVERAGE(P88,P87) -> 169.95 | Q89: =AVERAGE(Q88,Q87) -> 153.2 | R89: =AVERAGE(R88,R87) -> 147.55 | S89: =AVERAGE(S88,S87) -> 0 | T89: 148.4 | U89: =AVERAGE(U88,U87) -> 151.65 | V89: 154.3 | W89: =AVERAGE(W88,W87) -> 135.9 | X89: =AVERAGE(X88,X87) -> 150.8 | Y89: =AVERAGE(Y88,Y87) -> 161.55 | Z89: =AVERAGE(Z88,Z87) -> 144.25 | AA89: =AVERAGE(AA88,AA87) -> 148.5 | AB89: =AVERAGE(AB88,AB87) -> 150.1
A90: Rural | B90: 2020 | C90: May | D90: =AVERAGE(D89,D88) -> 145.8 | E90: =AVERAGE(E89,E88) -> 166.975 | F90: =AVERAGE(F89,F88) -> 147.25 | G90: =AVERAGE(G89,G88) -> 153.65 | H90: =AVERAGE(H89,H88) -> 135.2 | I90: =AVERAGE(I89,I88) -> 144.55 | J90: =AVERAGE(J89,J88) -> 157.5 | K90: =AVERAGE(K89,K88) -> 146 | ... AB90: =AVERAGE(AB89,AB88) -> 149.95
A91: Rural | B91: 2020 | C91: June | D91: 148.2 | E91: 190.3 | F91: 149.4 | G91: 153.3 | H91: 138.2 | I91: 143.2 | J91: 148.9 | K91: 150.3 | L91: 113.2 | M91: 159.8 | N91: 142.1 | O91: 161.8 | P91: 182.4 | Q91: 154.7 | R91: 150 | S91: =AVERAGE(S90,S89) -> 0 | T91: 144.9 | U91: 151.7 | V91: 158.2 | W91: 141.4 | X91: 153.2 | Y91: 161.8 | Z91: 151.2 | AA91: 151.7 | AB91: 152.7
A92: Rural | B92: 2020 | C92: July | D92: 148.2 | E92: 190.3 | F92: 149.4 | G92: 153.3 | H92: 138.2 | I92: 143.2 | J92: 148.9 | K92: 150.3 | L92: 113.2 | M92: 159.8 | N92: 142.1 | O92: 161.8 | P92: 182.4 | Q92: 154.7 | R92: 150 | S92: =AVERAGE(S91,S90) -> 0 | T92: 144.9 | U92: 151.7 | V92: 158.2 | W92: 141.4 | X92: 153.2 | Y92: 161.8 | Z92: 151.2 | AA92: 151.7 | AB92: 152.7
A93: Rural | B93: 2020 | C93: August | D93: 147.6 | E93: 187.2 | F93: 148.4 | G93: 153.3 | H93: 139.8 | I93: 146.9 | J93: 171 | K93: 149.9 | L93: 114.2 | M93: 160 | N93: 143.5 | O93: 161.5 | P93: 180.9 | Q93: 155.1 | R93: 149.3 | S93: =AVERAGE(S92,S91) -> 0 | T93: 145.8 | U93: 151.9 | V93: 158.8 | W93: 143.6 | X93: 152.2 | Y93: 162.7 | Z93: 153.6 | AA93: 153 | AB93: 154.7
A94: Rural | B94: 2020 | C94: September | D94: 146.9 | E94: 183.9 | F94: 149.5 | G94: 153.4 | H94: 140.4 | I94: 147 | J94: 178.8 | K94: 149.3 | L94: 115.1 | M94: 160 | N94: 145.4 | O94: 161.6 | P94: 182.9 | Q94: 155.4 | R94: 149.9 | S94: =AVERAGE(S93,S92) -> 0 | T94: 146.4 | U94: 151.6 | V94: 159.1 | W94: 144.6 | X94: 152.8 | Y94: 161.1 | Z94: 157.4 | AA94: 153.7 | AB94: 155.4
A95: Rural | B95: 2020 | C95: October | D95: 146 | E95: 186.3 | F95: 159.2 | G95: 153.6 | H95: 142.6 | I95: 147.2 | J95: 200.6 | K95: 150.3 | L95: 115.3 | M95: 160.9 | N95: 147.4 | O95: 161.9 | P95: 182.7 | Q95: 155.7 | R95: 150.6 | S95: =AVERAGE(S94,S93) -> 0 | T95: 146.8 | U95: 152 | V95: 159.5 | W95: 146.4 | X95: 152.4 | Y95: 162.5 | Z95: 156.2 | AA95: 154.3 | AB95: 157.5
A96: Rural | B96: 2020 | C96: November | D96: 145.4 | E96: 188.6 | F96: 171.6 | G96: 153.8 | H96: 145.4 | I96: 146.5 | J96: 222.2 | K96: 155.9 | L96: 114.9 | M96: 162 | N96: 150 | O96: 162.7 | P96: 183.4 | Q96: 156.3 | R96: 151 | S96: =AVERAGE(S95,S94) -> 0 | T96: 147.5 | U96: 152.8 | V96: 160.4 | W96: 146.1 | X96: 153.6 | Y96: 161.6 | Z96: 156.2 | AA96: 154.5 | AB96: 159.8
A97: Rural | B97: 2020 | C97: December | D97: 144.6 | E97: 188.5 | F97: 173.4 | G97: 154 | H97: 150 | I97: 145.9 | J97: 225.2 | K97: 159.5 | L97: 114.4 | M97: 163.5 | N97: 153.4 | O97: 163.6 | P97: 183.6 | Q97: 157 | R97: 151.6 | S97: =AVERAGE(S96,S95) -> 0 | T97: 148.7 | U97: 153.4 | V97: 161.6 | W97: 146.4 | X97: 153.9 | Y97: 162.9 | Z97: 156.6 | AA97: 155.2 | AB97: 160.7
A98: Rural | B98: 2021 | C98: January | D98: 143.4 | E98: 187.5 | F98: 173.4 | G98: 154 | H98: 154.8 | I98: 147 | J98: 187.8 | K98: 159.5 | L98: 113.8 | M98: 164.5 | N98: 156.1 | O98: 164.3 | P98: 184.6 | Q98: 157.5 | R98: 152.4 | S98: =AVERAGE(S97,S96) -> 0 | T98: 150.9 | U98: 153.9 | V98: 162.5 | W98: 147.5 | X98: 155.1 | Y98: 163.5 | Z98: 156.2 | AA98: 155.9 | AB98: 158.5
A99: Rural | B99: 2021 | C99: February | D99: 142.8 | E99: 184 | F99: 168 | G99: 154.4 | H99: 163 | I99: 147.8 | J99: 149.7 | K99: 158.3 | L99: 111.8 | M99: 165 | N99: 160 | O99: 165.8 | P99: 186.5 | Q99: 159.1 | R99: 153.9 | S99: =AVERAGE(S98,S97) -> 0 | T99: 154.4 | U99: 154.8 | V99: 164.3 | W99: 150.2 | X99: 157 | Y99: 163.6 | Z99: 155.2 | AA99: 157.2 | AB99: 156.7
A100: Rural | B100: 2021 | C100: March | D100: 142.5 | E100: 189.4 | F100: 163.2 | G100: 154.5 | H100: 168.2 | I100: 150.5 | J100: 141 | K100: 159.2 | L100: 111.7 | M100: 164 | N100: 160.6 | O100: 166.4 | P100: 186.1 | Q100: 159.6 | R100: 154.4 | S100: =AVERAGE(S99,S98) -> 0 | T100: 156 | U100: 154.8 | V100: 164.6 | W100: 151.3 | X100: 157.8 | Y100: 163.8 | Z100: 153.1 | AA100: 157.3 | AB100: 156.7
A101: Rural | B101: 2021 | C101: April | D101: 142.7 | E101: 195.5 | F101: 163.4 | G101: 155 | H101: 175.2 | I101: 160.6 | J101: 135.1 | K101: 161.1 | L101: 112.2 | M101: 164.4 | N101: 161.9 | O101: 166.8 | P101: 186.8 | Q101: 160.7 | R101: 155.1 | S101: =AVERAGE(S100,S99) -> 0 | T101: 156 | U101: 155.5 | V101: 165.3 | W101: 151.7 | X101: 158.6 | Y101: 164.1 | Z101: 154.6 | AA101: 158 | AB101: 157.6
A102: Rural | B102: 2021 | C102: May | D102: 145.1 | E102: 198.5 | F102: 168.6 | G102: 155.8 | H102: 184.4 | I102: 162.3 | J102: 138.4 | K102: 165.1 | L102: 114.3 | M102: 169.7 | N102: 164.6 | O102: 169.8 | P102: 189.6 | Q102: 165.3 | R102: 160.6 | S102: =AVERAGE(S101,S100) -> 0 | T102: 161.7 | U102: 158.8 | V102: 169.1 | W102: 153.2 | X102: 160 | Y102: 167.6 | Z102: 159.3 | AA102: 161.1 | AB102: 161.1
... A125: Rural | B125: 2023 | C125: April | D125: 173.3 | E125: 206.9 | F125: 167.9 | G125: 178.2 | H125: 178.5 | I125: 173.7 | J125: 142.8 | K125: 172.8 | L125: 120.4 | M125: 215.5 | N125: 178.2 | O125: 190.5 | P125: 199.5 | Q125: 190.7 | R125: 187.3 | S125: =AVERAGE(S124,S123) -> 0 | T125: 181.5 | U125: 179.1 | V125: 187.2 | W125: 169.4 | X125: 173.2 | Y125: 179.4 | Z125: 183.8 | AA125: 178.9 | AB125: 178.8
A126: Rural | B126: 2023 | C126: May | D126: 173.2 | E126: 211.5 | F126: 171 | G126: 179.6 | H126: 173.3 | I126: 169 | J126: 148.7 | K126: 174.9 | L126: 121.9 | M126: 221 | N126: 178.7 | O126: 191.1 | P126: 199.9 | Q126: 191.2 | R126: 187.9 | S126: 0 | T126: 182.5 | U126: 179.8 | V126: 187.8 | W126: 169.7 | X126: 173.8 | Y126: 180.3 | Z126: 184.9 | AA126: 179.5 | AB126: 179.8
A127: Rural+Urban | B127: 2013 | C127: January | D127: 108.4 | E127: 107.3 | F127: 110 | G127: 104.4 | H127: 105.1 | I127: 103.2 | J127: 102.2 | K127: 106 | L127: 106.2 | M127: 102.7 | N127: 104.9 | O127: 107.3 | P127: 105.1 | Q127: 106.3 | R127: 105.5 | S127: 100.3 | T127: 105.5 | U127: 104.8 | V127: 104 | W127: 103.2 | X127: 103.1 | Y127: 103.6 | Z127: 104.5 | AA127: 103.9 | AB127: 104.6
A128: Rural+Urban | B128: 2013 | C128: February | D128: 110.4 | E128: 110.2 | F128: 112.8 | G128: 104.9 | H128: 105.5 | I128: 103.6 | J128: 103.2 | K128: 105.3 | L128: 105.1 | M128: 102.8 | N128: 105.5 | O128: 108.3 | P128: 105.7 | Q128: 106.9 | R128: 106 | S128: 100.4 | T128: 106 | U128: 105.2 | V128: 104.5 | W128: 104.2 | X128: 103.6 | Y128: 103.9 | Z128: 104.5 | AA128: 104.4 | AB128: 105.3
A129: Rural+Urban | B129: 2013 | C129: March | D129: 111.4 | E129: 109.7 | F129: 111.2 | G129: 105.1 | H129: 104.9 | I129: 105.3 | J129: 102.2 | K129: 105 | L129: 104.2 | M129: 103 | N129: 106.2 | O129: 108.9 | P129: 106.6 | Q129: 107.4 | R129: 106.5 | S129: 100.4 | T129: 106.1 | U129: 105.6 | V129: 104.9 | W129: 105.1 | X129: 103.7 | Y129: 104 | Z129: 104.3 | AA129: 104.7 | AB129: 105.5
A130: Rural+Urban | B130: 2013 | C130: April | D130: 111.6 | E130: 110.9 | F130: 106.6 | G130: 105.7 | H130: 104.4 | I130: 108.9 | J130: 105.5 | K130: 105.3 | L130: 103.5 | M130: 103.3 | N130: 107.2 | O130: 109.6 | P130: 107.5 | Q130: 108 | R130: 107 | S130: 100.5 | T130: 106.5 | U130: 106.3 | V130: 105.3 | W130: 104.7 | X130: 104.2 | Y130: 105 | Z130: 102.9 | AA130: 104.8 | AB130: 106.1
A131: Rural+Urban | B131: 2013 | C131: May | D131: 112.3 | E131: 111.3 | F131: 104.7 | G131: 106.8 | H131: 103.9 | I131: 109.3 | J131: 112.9 | K131: 105.8 | L131: 103.1 | M131: 104.3 | N131: 108.1 | O131: 110.5 | P131: 108.6 | Q131: 108.7 | R131: 107.4 | S131: 100.5 | T131: 107.4 | U131: 106.9 | V131: 105.9 | W131: 104 | X131: 104.8 | Y131: 105.6 | Z131: 102.3 | AA131: 104.8 | AB131: 106.9
A132: Rural+Urban | B132: 2013 | C132: June | D132: 113.8 | E132: 114.9 | F132: 109.8 | G132: 107.9 | H132: 104.2 | I132: 110.7 | J132: 126.7 | K132: 106.3 | L132: 103.2 | M132: 105.7 | N132: 109 | O132: 111.6 | P132: 109.5 | Q132: 109.5 | R132: 108.1 | S132: 106.6 | T132: 108.3 | U132: 107.6 | V132: 106.4 | W132: 105.1 | X132: 105.4 | Y132: 107.4 | Z132: 102.8 | AA132: 105.8 | AB132: 109.3
A133: Rural+Urban | B133: 2013 | C133: July | D133: 114.8 | E133: 116.4 | F133: 111.9 | G133: 108.9 | H133: 104.3 | I133: 111.7 | J133: 140 | K133: 106.4 | L133: 103.3 | M133: 106.8 | N133: 109.6 | O133: 112.6 | P133: 110.3 | Q133: 110.2 | R133: 108.8 | S133: 107.7 | T133: 109.2 | U133: 108.2 | V133: 107 | W133: 107.1 | X133: 106.1 | Y133: 109.1 | Z133: 102.8 | AA133: 106.9 | AB133: 111
A134: Rural+Urban | B134: 2013 | C134: August | D134: 115.6 | E134: 117.2 | F134: 111.7 | G134: 109.6 | H134: 104.5 | I134: 109.8 | J134: 151.8 | K134: 106.5 | L134: 103.1 | M134: 107.4 | N134: 110.2 | O134: 113.4 | P134: 111.2 | Q134: 111 | R134: 109.4 | S134: 108.9 | T134: 109.7 | U134: 108.7 | V134: 107.5 | W134: 108 | X134: 106.6 | Y134: 109.9 | Z134: 105.4 | AA134: 107.9 | AB134: 112.4
...

Sheet Unpivoted
A1: Sector | B1: Year | C1: Month | D1: Categories | E1: Index Value
A2: Rural | B2: 2013 | C2: January | D2: Cereals and products | E2: 107.5
A3: Rural | B3: 2013 | C3: January | D3: Meat and fish | E3: 106.3
A4: Rural | B4: 2013 | C4: January | D4: Egg | E4: 108.1
A5: Rural | B5: 2013 | C5: January | D5: Milk and products | E5: 104.9
A6: Rural | B6: 2013 | C6: January | D6: Oils and fats | E6: 106.1
A7: Rural | B7: 2013 | C7: January | D7: Fruits | E7: 103.9
A8: Rural | B8: 2013 | C8: January | D8: Vegetables | E8: 101.9
A9: Rural | B9: 2013 | C9: January | D9: Pulses and products | E9: 106.1
A10: Rural | B10: 2013 | C10: January | D10: Sugar and Confectionery | E10: 106.8
A11: Rural | B11: 2013 | C11: January | D11: Spices | E11: 103.1
A12: Rural | B12: 2013 | C12: January | D12: Nonalcoholic beverages | E12: 104.8
A13: Rural | B13: 2013 | C13: January | D13: Prepared meals, Snacks, sweets etc. | E13: 106.7
... A9301: Urban | B9301: 2023 | C9301: May | D9301: General index | E9301: 178.2

Sheet Categories Bucket
A1: Categories | B1: Bucket
A2: Cereals and products | B2: Food And Bevereges
A3: Meat and fish | B3: Food And Bevereges
A4: Egg | B4: Food And Bevereges
A5: Milk and products | B5: Food And Bevereges
A6: Oils and fats | B6: Food And Bevereges
A7: Fruits | B7: Food And Bevereges
A8: Vegetables | B8: Food And Bevereges
A9: Pulses and products | B9: Food And Bevereges
A10: Sugar and Confectionery | B10: Food And Bevereges
A11: Spices | B11: Food And Bevereges
A12: Nonalcoholic beverages | B12: Food And Bevereges
... A26: General index | B26: General Index

Sheet Final Data
A1: Sector | B1: Year | C1: Month | D1: Specific Month | E1: Categories | F1: Index Value | G1: Bucket
A2: Rural | B2: 2013 | C2: January | D2: =DATEVALUE("1 "&_xlfn.CONCAT(Merge1_1[[#This Row],[Month]],"-",Merge1_1[[#This Row],[Year]])) -> 41275 | E2: Cereals and products | F2: 107.5 | G2: Food And Bevereges
A3: Rural | B3: 2013 | C3: February | D3: =DATEVALUE("1 "&_xlfn.CONCAT(Merge1_1[[#This Row],[Month]],"-",Merge1_1[[#This Row],[Year]])) -> 41306 | E3: Cereals and products | F3: 109.2 | G3: Food And Bevereges
A4: Rural | B4: 2013 | C4: January | D4: =DATEVALUE("1 "&_xlfn.CONCAT(Merge1_1[[#This Row],[Month]],"-",Merge1_1[[#This Row],[Year]])) -> 41275 | E4: Meat and fish | F4: 106.3 | G4: Food And Bevereges
A5: Rural | B5: 2013 | C5: January | D5: =DATEVALUE("1 "&_xlfn.CONCAT(Merge1_1[[#This Row],[Month]],"-",Merge1_1[[#This Row],[Year]])) -> 41275 | E5: Egg | F5: 108.1 | G5: Food And Bevereges
A6: Rural | B6: 2013 | C6: January | D6: =DATEVALUE("1 "&_xlfn.CONCAT(Merge1_1[[#This Row],[Month]],"-",Merge1_1[[#This Row],[Year]])) -> 41275 | E6: Milk and products | F6: 104.9 | G6: Food And Bevereges
A7: Rural | B7: 2013 | C7: January | D7: =DATEVALUE("1 "&_xlfn.CONCAT(Merge1_1[[#This Row],[Month]],"-",Merge1_1[[#This Row],[Year]])) -> 41275 | E7: Oils and fats | F7: 106.1 | G7: Food And Bevereges
A8: Rural | B8: 2013 | C8: January | D8: =DATEVALUE("1 "&_xlfn.CONCAT(Merge1_1[[#This Row],[Month]],"-",Merge1_1[[#This Row],[Year]])) -> 41275 | E8: Fruits | F8: 103.9 | G8: Food And Bevereges
A9: Rural | B9: 2013 | C9: January | D9: =DATEVALUE("1 "&_xlfn.CONCAT(Merge1_1[[#This Row],[Month]],"-",Merge1_1[[#This Row],[Year]])) -> 41275 | E9: Vegetables | F9: 101.9 | G9: Food And Bevereges
A10: Rural | B10: 2013 | C10: January | D10: =DATEVALUE("1 "&_xlfn.CONCAT(Merge1_1[[#This Row],[Month]],"-",Merge1_1[[#This Row],[Year]])) -> 41275 | E10: Pulses and products | F10: 106.1 | G10: Food And Bevereges
A11: Rural | B11: 2013 | C11: January | D11: =DATEVALUE("1 "&_xlfn.CONCAT(Merge1_1[[#This Row],[Month]],"-",Merge1_1[[#This Row],[Year]])) -> 41275 | E11: Sugar and Confectionery | F11: 106.8 | G11: Food And Bevereges
A12: Rural | B12: 2013 | C12: January | D12: =DATEVALUE("1 "&_xlfn.CONCAT(Merge1_1[[#This Row],[Month]],"-",Merge1_1[[#This Row],[Year]])) -> 41275 | E12: Spices | F12: 103.1 | G12: Food And Bevereges
A13: Rural | B13: 2013 | C13: January | D13: =DATEVALUE("1 "&_xlfn.CONCAT(Merge1_1[[#This Row],[Month]],"-",Merge1_1[[#This Row],[Year]])) -> 41275 | E13: Nonalcoholic beverages | F13: 104.8 | G13: Food And Bevereges
... A9301: Urban | B9301: 2023 | C9301: May | D9301: =DATEVALUE("1 "&_xlfn.CONCAT(Merge1_1[[#This Row],[Month]],"-",Merge1_1[[#This Row],[Year]])) -> 45047 | E9301: General index | F9301: 178.2 | G9301: General Index

Sheet Bucket1
A1: Categories | B1: Bucket
A2: Cereals and products | B2: Food And Bevereges
A3: Meat and fish | B3: Food And Bevereges
A4: Egg | B4: Food And Bevereges
A5: Milk and products | B5: Food And Bevereges
A6: Oils and fats | B6: Food And Bevereges
A7: Fruits | B7: Food And Bevereges
A8: Vegetables | B8: Food And Bevereges
A9: Pulses and products | B9: Food And Bevereges
A10: Sugar and Confectionery | B10: Food And Bevereges
A11: Spices | B11: Food And Bevereges
A12: Nonalcoholic beverages | B12: Food And Bevereges
... A26: General index | B26: General Index

Sheet BUCKETING
A1: Sector | B1: Year | C1: Month | D1: Specific Month | E1: Date Value | F1: Cereals and products | G1: Meat and fish | H1: Egg | I1: Milk and products | J1: Oils and fats | K1: Fruits | L1: Vegetables | M1: Pulses and products | N1: Sugar and Confectionery | O1: Spices | P1: Nonalcoholic beverages | Q1: Prepared meals, snacks, sweets etc. | R1: FOOD AND BEVERAGES | S1: Food and beverages2 | T1: Clothing | U1: Footwear | V1: CLOTHING AND FOOTWEAR | W1: Clothing and footwear3 | X1: Housing | Y1: Health | Z1: Education | AA1: ESSENTIAL | AB1: Fuel and light | AC1: Transport and communication | AD1: ENERGY | AE1: Household goods and services | AF1: Recreation and amusement | AG1: Personal care and effects | AH1: Miscellaneous | AI1: Pan, tobacco and intoxicants | AJ1: LUXURY | AK1: General index
A2: Rural | B2: 2013 | C2: January | D2: =_xlfn.CONCAT(C2, " ",B2) -> January 2013 | E2: =DATEVALUE("1 "&D2) -> 41275 | F2: 107.5 | G2: 106.3 | H2: 108.1 | I2: 104.9 | J2: 106.1 | K2: 103.9 | L2: 101.9 | M2: 106.1 | N2: 106.8 | O2: 103.1 | P2: 104.8 | Q2: 106.7 | R2: =SUM(F2:Q2) -> 1266.2 | S2: 105.5 | T2: 106.5 | U2: 105.8 | V2: =SUM(T2:U2) -> 212.3 | W2: 106.4 | X2: 0 | Y2: 104 | Z2: 103.8 | AA2: =SUM(X2:Z2) -> 207.8 | AB2: 105.5 | AC2: 103.3 | AD2: =SUM(AB2:AC2) -> 208.8 | AE2: 104.8 | AF2: 103.4 | AG2: 104.7 | AH2: 104 | AI2: 105.1 | AJ2: =SUM(AE2:AI2) -> 522 | AK2: 105.1
A3: Rural | B3: 2013 | C3: February | D3: =_xlfn.CONCAT(C3, " ",B3) -> February 2013 | E3: =DATEVALUE("1 "&D3) -> 41306 | F3: 109.2 | G3: 108.7 | H3: 110.2 | I3: 105.4 | J3: 106.7 | K3: 104 | L3: 102.4 | M3: 105.9 | N3: 105.7 | O3: 103.1 | P3: 105.1 | Q3: 107.7 | R3: =SUM(F3:Q3) -> 1274.1 | S3: 106.3 | T3: 107.1 | U3: 106.3 | V3: =SUM(T3:U3) -> 213.4 | W3: 107 | X3: 0 | Y3: 104.4 | Z3: 104.1 | AA3: =SUM(X3:Z3) -> 208.5 | AB3: 106.2 | AC3: 103.9 | AD3: =SUM(AB3:AC3) -> 210.1 | AE3: 105.2 | AF3: 104 | AG3: 104.6 | AH3: 104.4 | AI3: 105.6 | AJ3: =SUM(AE3:AI3) -> 523.8 | AK3: 105.8
A4: Rural | B4: 2013 | C4: March | D4: =_xlfn.CONCAT(C4, " ",B4) -> March 2013 | E4: =DATEVALUE("1 "&D4) -> 41334 | F4: 110.2 | G4: 108.8 | H4: 109.9 | I4: 105.6 | J4: 106.2 | K4: 105.7 | L4: 101.4 | M4: 105.7 | N4: 105 | O4: 103.3 | P4: 105.6 | Q4: 108.2 | R4: =SUM(F4:Q4) -> 1275.6 | S4: 106.6 | T4: 107.6 | U4: 106.8 | V4: =SUM(T4:U4) -> 214.4 | W4: 107.5 | X4: 0 | Y4: 104.7 | Z4: 104.3 | AA4: =SUM(X4:Z4) -> 209 | AB4: 106.1 | AC4: 104.6 | AD4: =SUM(AB4:AC4) -> 210.7 | AE4: 105.6 | AF4: 104 | AG4: 104.3 | AH4: 104.6 | AI4: 106.5 | AJ4: =SUM(AE4:AI4) -> 525 | AK4: 106
A5: Rural | B5: 2013 | C5: April | D5: =_xlfn.CONCAT(C5, " ",B5) -> April 2013 | E5: =DATEVALUE("1 "&D5) -> 41365 | F5: 110.2 | G5: 109.5 | H5: 106.9 | I5: 106.3 | J5: 105.7 | K5: 108.3 | L5: 103.4 | M5: 105.7 | N5: 104.2 | O5: 103.2 | P5: 106.5 | Q5: 108.8 | R5: =SUM(F5:Q5) -> 1278.7 | S5: 107.1 | T5: 108.1 | U5: 107.4 | V5: =SUM(T5:U5) -> 215.5 | W5: 108 | X5: 0 | Y5: 105.1 | Z5: 104.8 | AA5: =SUM(X5:Z5) -> 209.9 | AB5: 106.5 | AC5: 104.4 | AD5: =SUM(AB5:AC5) -> 210.9 | AE5: 106.1 | AF5: 104.5 | AG5: 102.7 | AH5: 104.6 | AI5: 107.1 | AJ5: =SUM(AE5:AI5) -> 525 | AK5: 106.4
A6: Rural | B6: 2013 | C6: May | D6: =_xlfn.CONCAT(C6, " ",B6) -> May 2013 | E6: =DATEVALUE("1 "&D6) -> 41395 | F6: 110.9 | G6: 109.8 | H6: 105.9 | I6: 107.5 | J6: 105.3 | K6: 108.1 | L6: 107.3 | M6: 106.1 | N6: 103.7 | O6: 104 | P6: 107.4 | Q6: 109.9 | R6: =SUM(F6:Q6) -> 1285.9 | S6: 108.1 | T6: 108.8 | U6: 107.9 | V6: =SUM(T6:U6) -> 216.7 | W6: 108.6 | X6: 0 | Y6: 105.7 | Z6: 105.5 | AA6: =SUM(X6:Z6) -> 211.2 | AB6: 107.5 | AC6: 104.1 | AD6: =SUM(AB6:AC6) -> 211.6 | AE6: 106.8 | AF6: 105 | AG6: 102.1 | AH6: 104.8 | AI6: 108.1 | AJ6: =SUM(AE6:AI6) -> 526.8 | AK6: 107.2
A7: Rural | B7: 2013 | C7: June | D7: =_xlfn.CONCAT(C7, " ",B7) -> June 2013 | E7: =DATEVALUE("1 "&D7) -> 41426 | F7: 112.3 | G7: 112.1 | H7: 108.1 | I7: 108.3 | J7: 105.9 | K7: 109.2 | L7: 118 | M7: 106.8 | N7: 104.1 | O7: 105.4 | P7: 108.2 | Q7: 111 | R7: =SUM(F7:Q7) -> 1309.4 | S7: 110.6 | T7: 109.7 | U7: 108.8 | V7: =SUM(T7:U7) -> 218.5 | W7: 109.5 | X7: 0 | Y7: 106.3 | Z7: 106.5 | AA7: =SUM(X7:Z7) -> 212.8 | AB7: 108.5 | AC7: 105 | AD7: =SUM(AB7:AC7) -> 213.5 | AE7: 107.5 | AF7: 105.6 | AG7: 102.5 | AH7: 105.5 | AI7: 109 | AJ7: =SUM(AE7:AI7) -> 530.1 | AK7: 108.9
A8: Rural | B8: 2013 | C8: July | D8: =_xlfn.CONCAT(C8, " ",B8) -> July 2013 | E8: =DATEVALUE("1 "&D8) -> 41456 | F8: 113.4 | G8: 114.9 | H8: 110.5 | I8: 109.3 | J8: 106.2 | K8: 110.3 | L8: 129.2 | M8: 107.1 | N8: 104.3 | O8: 106.4 | P8: 109.1 | Q8: 112.1 | R8: =SUM(F8:Q8) -> 1332.8 | S8: 113.1 | T8: 110.5 | U8: 109.5 | V8: =SUM(T8:U8) -> 220 | W8: 110.3 | X8: 0 | Y8: 106.9 | Z8: 107.8 | AA8: =SUM(X8:Z8) -> 214.7 | AB8: 109.5 | AC8: 106.8 | AD8: =SUM(AB8:AC8) -> 216.3 | AE8: 108.3 | AF8: 106.4 | AG8: 102.5 | AH8: 106.5 | AI8: 109.8 | AJ8: =SUM(AE8:AI8) -> 533.5 | AK8: 110.7
A9: Rural | B9: 2013 | C9: August | D9: =_xlfn.CONCAT(C9, " ",B9) -> August 2013 | E9: =DATEVALUE("1 "&D9) -> 41487 | F9: 114.3 | G9: 115.4 | H9: 111.1 | I9: 110 | J9: 106.4 | K9: 110.8 | L9: 138.9 | M9: 107.4 | N9: 104.1 | O9: 106.9 | P9: 109.7 | Q9: 112.6 | R9: =SUM(F9:Q9) -> 1347.6 | S9: 114.9 | T9: 111.3 | U9: 110.2 | V9: =SUM(T9:U9) -> 221.5 | W9: 111.1 | X9: 0 | Y9: 107.5 | Z9: 108.7 | AA9: =SUM(X9:Z9) -> 216.2 | AB9: 109.9 | AC9: 107.8 | AD9: =SUM(AB9:AC9) -> 217.7 | AE9: 108.7 | AF9: 106.8 | AG9: 105 | AH9: 107.5 | AI9: 110.7 | AJ9: =SUM(AE9:AI9) -> 538.7 | AK9: 112.1
A10: Rural | B10: 2013 | C10: September | D10: =_xlfn.CONCAT(C10, " ",B10) -> September 2013 | E10: =DATEVALUE("1 "&D10) -> 41518 | F10: 115.4 | G10: 115.7 | H10: 111.7 | I10: 111 | J10: 107.4 | K10: 110.9 | L10: 154 | M10: 108.1 | N10: 104.2 | O10: 107.9 | P10: 110.4 | Q10: 114 | R10: =SUM(F10:Q10) -> 1370.7 | S10: 117.8 | T10: 112.7 | U10: 111.4 | V10: =SUM(T10:U10) -> 224.1 | W10: 112.5 | X10: 0 | Y10: 108.3 | Z10: 109.8 | AA10: =SUM(X10:Z10) -> 218.1 | AB10: 111.1 | AC10: 109.3 | AD10: =SUM(AB10:AC10) -> 220.4 | AE10: 109.6 | AF10: 107.7 | AG10: 106.7 | AH10: 108.7 | AI10: 111.7 | AJ10: =SUM(AE10:AI10) -> 544.4 | AK10: 114.2
A11: Rural | B11: 2013 | C11: October | D11: =_xlfn.CONCAT(C11, " ",B11) -> October 2013 | E11: =DATEVALUE("1 "&D11) -> 41548 | F11: 116.3 | G11: 115.4 | H11: 112.6 | I11: 111.7 | J11: 107.7 | K11: 113.2 | L11: 164.9 | M11: 108.3 | N11: 103.9 | O11: 108.2 | P11: 111.1 | Q11: 114.9 | R11: =SUM(F11:Q11) -> 1388.2 | S11: 119.8 | T11: 113.6 | U11: 112.3 | V11: =SUM(T11:U11) -> 225.9 | W11: 113.4 | X11: 0 | Y11: 108.9 | Z11: 110.2 | AA11: =SUM(X11:Z11) -> 219.1 | AB11: 111.6 | AC11: 109.3 | AD11: =SUM(AB11:AC11) -> 220.9 | AE11: 110.4 | AF11: 108.3 | AG11: 107.5 | AH11: 109.1 | AI11: 112.2 | AJ11: =SUM(AE11:AI11) -> 547.5 | AK11: 115.5
A12: Rural | B12: 2013 | C12: November | D12: =_xlfn.CONCAT(C12, " ",B12) -> November 2013 | E12: =DATEVALUE("1 "&D12) -> 41579 | F12: 117.3 | G12: 114.9 | H12: 116.2 | I12: 112.8 | J12: 108.9 | K12: 116.6 | L12: 178.1 | M12: 109.1 | N12: 103.6 | O12: 109 | P12: 111.8 | Q12: 116 | R12: =SUM(F12:Q12) -> 1414.3 | S12: 122.5 | T12: 114.6 | U12: 113.1 | V12: =SUM(T12:U12) -> 227.7 | W12: 114.4 | X12: 0 | Y12: 109.7 | Z12: 111 | AA12: =SUM(X12:Z12) -> 220.7 | AB12: 112.6 | AC12: 109.6 | AD12: =SUM(AB12:AC12) -> 222.2 | AE12: 111.3 | AF12: 108.7 | AG12: 108.2 | AH12: 109.8 | AI12: 112.8 | AJ12: =SUM(AE12:AI12) -> 550.8 | AK12: 117.4
A13: Rural | B13: 2013 | C13: December | D13: =_xlfn.CONCAT(C13, " ",B13) -> December 2013 | E13: =DATEVALUE("1 "&D13) -> 41609 | F13: 118.4 | G13: 115.9 | H13: 120.4 | I13: 113.8 | J13: 109.5 | K13: 115.5 | L13: 145.7 | M13: 109.5 | N13: 102.9 | O13: 109.8 | P13: 112.1 | Q13: 116.8 | R13: =SUM(F13:Q13) -> 1390.3 | S13: 118.7 | T13: 115.8 | U13: 114 | V13: =SUM(T13:U13) -> 229.8 | W13: 115.5 | X13: 0 | Y13: 110.1 | Z13: 111.6 | AA13: =SUM(X13:Z13) -> 221.7 | AB13: 112.8 | AC13: 109.9 | AD13: =SUM(AB13:AC13) -> 222.7 | AE13: 112.1 | AF13: 109.2 | AG13: 108.1 | AH13: 110.1 | AI13: 113.6 | AJ13: =SUM(AE13:AI13) -> 553.1 | AK13: 115.5
... A373: Urban | B373: 2023 | C373: May | D373: =_xlfn.CONCAT(C373, " ",B373) -> May 2023 | E373: =DATEVALUE("1 "&D373) -> 45047 | F373: 174.7 | G373: 219.4 | H373: 176.7 | I373: 179.4 | J373: 164.4 | K373: 175.8 | L373: 185 | M373: 176.9 | N373: 124.2 | O373: 211.9 | P373: 165.9 | Q373: 197.7 | R373: =SUM(F373:Q373) -> 2152 | S373: 183.1 | T373: 181.3 | U373: 168.1 | V373: =SUM(T373:U373) -> 349.4 | W373: 179.3 | X373: 175.6 | Y373: 182.2 | Z373: 174.8 | AA373: =SUM(X373:Z373) -> 532.6 | AB373: 183.4 | AC373: 160.4 | AD373: =SUM(AB373:AC373) -> 343.8 | AE373: 170.1 | AF373: 169.2 | AG373: 185.6 | AH373: 171.6 | AI373: 204.2 | AJ373: =SUM(AE373:AI373) -> 900.7 | AK373: 178.2

Sheet BUCKET
A1: SECTOR | B1: YEAR | C1: MONTH | D1: FOOD AND BEVERAGES | E1: CLOTHING AND FOOTWEAR | F1: ESSENTIAL | G1: ENERGY | H1: LUXURY | I1: GENERAL INDEX
A2: Rural | B2: 2013 | C2: January | D2: =BUCKETING!R2 -> 1266.2 | E2: =BUCKETING!V2 -> 212.3 | F2: =BUCKETING!AA2 -> 207.8 | G2: =BUCKETING!AD2 -> 208.8 | H2: =BUCKETING!AJ2 -> 522 | I2: =BUCKETING!AK2 -> 105.1
A3: Rural | B3: 2013 | C3: February | D3: =BUCKETING!R3 -> 1274.1 | E3: =BUCKETING!V3 -> 213.4 | F3: =BUCKETING!AA3 -> 208.5 | G3: =BUCKETING!AD3 -> 210.1 | H3: =BUCKETING!AJ3 -> 523.8 | I3: =BUCKETING!AK3 -> 105.8
A4: Rural | B4: 2013 | C4: March | D4: =BUCKETING!R4 -> 1275.6 | E4: =BUCKETING!V4 -> 214.4 | F4: =BUCKETING!AA4 -> 209 | G4: =BUCKETING!AD4 -> 210.7 | H4: =BUCKETING!AJ4 -> 525 | I4: =BUCKETING!AK4 -> 106
A5: Rural | B5: 2013 | C5: April | D5: =BUCKETING!R5 -> 1278.7 | E5: =BUCKETING!V5 -> 215.5 | F5: =BUCKETING!AA5 -> 209.9 | G5: =BUCKETING!AD5 -> 210.9 | H5: =BUCKETING!AJ5 -> 525 | I5: =BUCKETING!AK5 -> 106.4
A6: Rural | B6: 2013 | C6: May | D6: =BUCKETING!R6 -> 1285.9 | E6: =BUCKETING!V6 -> 216.7 | F6: =BUCKETING!AA6 -> 211.2 | G6: =BUCKETING!AD6 -> 211.6 | H6: =BUCKETING!AJ6 -> 526.8 | I6: =BUCKETING!AK6 -> 107.2
A7: Rural | B7: 2013 | C7: June | D7: =BUCKETING!R7 -> 1309.4 | E7: =BUCKETING!V7 -> 218.5 | F7: =BUCKETING!AA7 -> 212.8 | G7: =BUCKETING!AD7 -> 213.5 | H7: =BUCKETING!AJ7 -> 530.1 | I7: =BUCKETING!AK7 -> 108.9
A8: Rural | B8: 2013 | C8: July | D8: =BUCKETING!R8 -> 1332.8 | E8: =BUCKETING!V8 -> 220 | F8: =BUCKETING!AA8 -> 214.7 | G8: =BUCKETING!AD8 -> 216.3 | H8: =BUCKETING!AJ8 -> 533.5 | I8: =BUCKETING!AK8 -> 110.7
A9: Rural | B9: 2013 | C9: August | D9: =BUCKETING!R9 -> 1347.6 | E9: =BUCKETING!V9 -> 221.5 | F9: =BUCKETING!AA9 -> 216.2 | G9: =BUCKETING!AD9 -> 217.7 | H9: =BUCKETING!AJ9 -> 538.7 | I9: =BUCKETING!AK9 -> 112.1
A10: Rural | B10: 2013 | C10: September | D10: =BUCKETING!R10 -> 1370.7 | E10: =BUCKETING!V10 -> 224.1 | F10: =BUCKETING!AA10 -> 218.1 | G10: =BUCKETING!AD10 -> 220.4 | H10: =BUCKETING!AJ10 -> 544.4 | I10: =BUCKETING!AK10 -> 114.2
A11: Rural | B11: 2013 | C11: October | D11: =BUCKETING!R11 -> 1388.2 | E11: =BUCKETING!V11 -> 225.9 | F11: =BUCKETING!AA11 -> 219.1 | G11: =BUCKETING!AD11 -> 220.9 | H11: =BUCKETING!AJ11 -> 547.5 | I11: =BUCKETING!AK11 -> 115.5
A12: Rural | B12: 2013 | C12: November | D12: =BUCKETING!R12 -> 1414.3 | E12: =BUCKETING!V12 -> 227.7 | F12: =BUCKETING!AA12 -> 220.7 | G12: =BUCKETING!AD12 -> 222.2 | H12: =BUCKETING!AJ12 -> 550.8 | I12: =BUCKETING!AK12 -> 117.4
A13: Rural | B13: 2013 | C13: December | D13: =BUCKETING!R13 -> 1390.3 | E13: =BUCKETING!V13 -> 229.8 | F13: =BUCKETING!AA13 -> 221.7 | G13: =BUCKETING!AD13 -> 222.7 | H13: =BUCKETING!AJ13 -> 553.1 | I13: =BUCKETING!AK13 -> 115.5
... A373: Urban | B373: 2023 | C373: May | D373: =BUCKETING!R373 -> 2152 | E373: =BUCKETING!V373 -> 349.4 | F373: =BUCKETING!AA373 -> 532.6 | G373: =BUCKETING!AD373 -> 343.8 | H373: =BUCKETING!AJ373 -> 900.7 | I373: =BUCKETING!AK373 -> 178.2

Sheet Q1
A1: 1. Based on the latest month's data, identify the contribution of different broader categories (food, energy, transportation, education, etc.) towards the CPI basket. Broader categories (buckets) can be created by combining similar categories into one bucket; Ex.: Meals, Beverages, Cereals, can be clubbed to create "Food" category, etc.
A5: • Which broader category has the highest contribution towards towards CPI Calculation
A6: • Contribution is calculated by evaluating the underlying index values for broader category and should add to 100% when contribution from different broader categories are added. | Q6: BUCKET
Q8: FOOD AND BEVERAGES | R8: CLOTHING AND FOOTWEAR | S8: ESSENTIAL | T8: ENERGY | U8: LUXURY
A9: SECTOR | B9: YEAR | C9: MONTH | D9: FOOD AND BEVERAGES | E9: CLOTHING AND FOOTWEAR | F9: ESSENTIAL | G9: ENERGY | H9: LUXURY | I9: TOTAL
A10: Rural | B10: 2023 | C10: May | D10: 2113.9 | E10: 379.1 | F10: 368.1 | G10: 352.2 | H10: 917.9 | I10: =SUM(D10:H10) -> 4131.2 | Q10: Cereals and products | R10: Clothing | S10: Housing | T10: Fuel and light | U10: Household goods and services
A11: Rural+Urban | B11: 2023 | C11: May | D11: 2127.8 | E11: 367 | F11: 538.4 | G11: 347.6 | H11: 908.3 | I11: =SUM(D11:H11) -> 4289.1 | Q11: Meat and fish | R11: Footwear | S11: Health | T11: Transport and communication | U11: Recreation and amusement
A12: Urban | B12: 2023 | C12: May | D12: 2152 | E12: 349.4 | F12: 532.6 | G12: 343.8 | H12: 900.7 | I12: =SUM(D12:H12) -> 4278.5 | Q12: Egg | S12: Education | U12: Personal care and effects
Q13: Milk and products | U13: Miscellaneous
A14: SECTOR | B14: YEAR | C14: MONTH | D14: FOOD AND BEVERAGES | E14: CLOTHING AND FOOTWEAR | F14: ESSENTIAL | G14: ENERGY | H14: LUXURY | I14: TOTAL | Q14: Oils and fats | U14: Pan, tobacco and intoxicants
A15: Rural | B15: 2023 | C15: May | D15: =D10/$I$10 -> 0.51169152 | E15: =E10/$I$10 -> 0.091765105 | F15: =F10/$I$10 -> 0.08910244 | G15: =G10/$I$10 -> 0.085253679 | H15: =H10/$I$10 -> 0.22218726 | I15: =I10/$I$10 -> 1 | Q15: Fruits
A16: Rural+Urban | B16: 2023 | C16: May | D16: =D11/$I$11 -> 0.49609475 | E16: =E11/$I$11 -> 0.085565736 | F16: =F11/$I$11 -> 0.1255275 | G16: =G11/$I$11 -> 0.081042643 | H16: =H11/$I$11 -> 0.21176937 | I16: =I11/$I$11 -> 1 | Q16: Vegetables
A17: Urban | B17: 2023 | C17: May | D17: =D12/$I$12 -> 0.50298002 | E17: =E12/$I$12 -> 0.081664135 | F17: =F12/$I$12 -> 0.12448288 | G17: =G12/$I$12 -> 0.080355265 | H17: =H12/$I$12 -> 0.2105177 | I17: =I12/$I$12 -> 1 | Q17: Pulses and products
Q18: Sugar and Confectionery
Q19: Spices
Q20: Nonalcoholic beverages
Q21: Prepared meals, snacks, sweets etc.
A32: Findings : | B32: Food and Beverages has the highest contribution of 49.6% for Rural + Urban Sector towards CPI Calculations.

Sheet Q2
A1: 2. A trend of Y-o-Y increase in CPI (rural + urban) inflation starting 2017 for the entire basket of products combined.
A2: • Create a graph depicting the growth rate Y-o-Y and identify the year with highest inflation rate
A3: • Highlight the reason why the year has the highest inflation (based on research).
A5: YEAR | B5: CPI | C5: INFLATION | J5: Sector | K5: Rural+Urban | S5: Sector | T5: Rural+Urban | V5: Difference
A6: 2017 | B6: 131.16667 | J6: Year | K6: 2017 | L6: 2018 | M6: 2019 | N6: 2020 | O6: 2021 | P6: 2022 | Q6: 2023 | S6: Year | T6: 2020 | U6: 2021
A7: 2018 | B7: 136.47083 | C7: =(B7-B6)/B6 -> 0.040438374 | J7: Month | K7: May | L7: May | M7: May | N7: May | O7: May | P7: May | Q7: May | S7: Month | T7: May | U7: May
A8: 2019 | B8: 140.50833 | C8: =(B8-B7)/B7 -> 0.029585076 | J8: Cereals and products | K8: 132.9 | L8: 136.6 | M8: 138.3 | N8: 146.9 | O8: 146.3 | P8: 154.1 | Q8: 173.7 | S8: Cereals and products | T8: 146.9 | U8: 146.3 | V8: =(U8-T8)/T8 -> -0.0040844112
A9: 2020 | B9: 148.07188 | C9: =(B9-B8)/B8 -> 0.053829844 | J9: Meat and fish | K9: 141.6 | L9: 146.6 | M9: 158.5 | N9: 167.125 | O9: 200.5 | P9: 217 | Q9: 214.3 | S9: Meat and fish | T9: 167.125 | U9: 200.5 | V9: =(U9-T9)/T9 -> 0.19970082
A10: 2021 | B10: 161.4 | C10: =(B10-B9)/B9 -> 0.090011185 | J10: Egg | K10: 126.3 | L10: 133.6 | M10: 136 | N10: 148.45 | O10: 170.3 | P10: 162.4 | Q10: 173.2 | S10: Egg | T10: 148.45 | U10: 170.3 | V10: =(U10-T10)/T10 -> 0.14718761
A11: 2022 | B11: 171.57083 | C11: =(B11-B10)/B10 -> 0.063016316 | J11: Milk and products | K11: 137.7 | L11: 142.1 | M11: 142.5 | N11: 153.55 | O11: 156.1 | P11: 164.9 | Q11: 179.5 | S11: Milk and products | T11: 153.55 | U11: 156.1 | V11: =(U11-T11)/T11 -> 0.016606968
A12: 2023 | B12: 178.7125 | C12: =(B12-B11)/B11 -> 0.041625179 | J12: Oils and fats | K12: 118.1 | L12: 121 | M12: 122 | N12: 133.15 | O12: 178.7 | P12: 202.4 | Q12: 170 | S12: Oils and fats | T12: 133.15 | U12: 178.7 | V12: =(U12-T12)/T12 -> 0.34209538
J13: Fruits | K13: 137.9 | L13: 154.6 | M13: 146.5 | N13: 146.2 | O13: 167.1 | P13: 171 | Q13: 172.2 | S13: Fruits | T13: 146.2 | U13: 167.1 | V13: =(U13-T13)/T13 -> 0.14295486
J14: Vegetables | K14: 125.6 | L14: 135.6 | M14: 143 | N14: 162.95 | O14: 147.9 | P14: 174.9 | Q14: 161 | S14: Vegetables | T14: 162.95 | U14: 147.9 | V14: =(U14-T14)/T14 -> -0.09235962
J15: Pulses and products | K15: 138.3 | L15: 122.3 | M15: 124.9 | N15: 145.75 | O15: 165.4 | P15: 164.7 | Q15: 175.6 | S15: Pulses and products | T15: 145.75 | U15: 165.4 | V15: =(U15-T15)/T15 -> 0.1348199
J16: Sugar and Confectionery | K16: 119.4 | L16: 109.6 | M16: 109.9 | N16: 116.75 | O16: 114.8 | P16: 119.7 | Q16: 122.7 | S16: Sugar and Confectionery | T16: 116.75 | U16: 114.8 | V16: =(U16-T16)/T16 -> -0.016702355
J17: Spices | K17: 136 | L17: 138.1 | M17: 139.9 | N17: 155.15 | O17: 168.2 | P17: 184.9 | Q17: 218 | S17: Spices | T17: 155.15 | U17: 168.2 | V17: =(U17-T17)/T17 -> 0.08411215
J18: Nonalcoholic beverages | K18: 127.6 | L18: 129.9 | M18: 134 | N18: 136.75 | O18: 159.3 | P18: 167.1 | Q18: 173.4 | S18: Nonalcoholic beverages | T18: 136.75 | U18: 159.3 | V18: =(U18-T18)/T18 -> 0.16489945
J19: Prepared meals, snacks, sweets etc. | K19: 144.5 | L19: 151.7 | M19: 155.5 | N19: 159.475 | O19: 170.4 | P19: 182.5 | Q19: 194.2 | S19: Prepared meals, snacks, sweets etc. | T19: 159.475 | U19: 170.4 | V19: =(U19-T19)/T19 -> 0.068506035
J20: Clothing | K20: 138.2 | L20: 146 | M20: 148.4 | N20: 151.1 | O20: 161.8 | P20: 175.6 | Q20: 187.3 | S20: Clothing | T20: 151.1 | U20: 161.8 | V20: =(U20-T20)/T20 -> 0.07081403
J21: Footwear | K21: 131.4 | L21: 137.4 | M21: 140.4 | N21: 141.85 | O21: 152.1 | P21: 168.4 | Q21: 179.7 | S21: Footwear | T21: 141.85 | U21: 152.1 | V21: =(U21-T21)/T21 -> 0.072259429
J22: Housing | K22: 132.1 | L22: 143.2 | M22: 150.1 | N22: 155.05 | O22: 161.6 | P22: 167.5 | Q22: 175.6 | S22: Housing | T22: 155.05 | U22: 161.6 | V22: =(U22-T22)/T22 -> 0.042244437
J23: Health | K23: 128.4 | L23: 136 | M23: 146.9 | N23: 151.5 | O23: 165.8 | P23: 174.8 | Q23: 185.7 | S23: Health | T23: 151.5 | U23: 165.8 | V23: =(U23-T23)/T23 -> 0.094389439
J24: Education | K24: 134.8 | L24: 142.1 | M24: 151.6 | N24: 156.125 | O24: 161.2 | P24: 167.9 | Q24: 177.1 | S24: Education | T24: 156.125 | U24: 161.2 | V24: =(U24-T24)/T24 -> 0.032506005
A25: Findings : | B25: The year 2021 has the highest inflation of 9% | J25: Fuel and light | K25: 129.4 | L25: 136.9 | M25: 140.3 | N25: 146.5 | O25: 159.4 | P25: 174.6 | Q25: 182.8 | S25: Fuel and light | T25: 146.5 | U25: 159.4 | V25: =(U25-T25)/T25 -> 0.088054608
A26: Insights : | B26: Sudden growth of 34.2% in Oils & Fats category is the main reason for the highest Inflation | J26: Transport and communication | K26: 116.7 | L26: 122.9 | M26: 124.9 | N26: 130 | O26: 148.9 | P26: 163 | Q26: 164.8 | S26: Transport and communication | T26: 130 | U26: 148.9 | V26: =(U26-T26)/T26 -> 0.14538462
J27: Household goods and services | K27: 130.9 | L27: 137.4 | M27: 143.7 | N27: 146.4 | O27: 154.7 | P27: 165.2 | Q27: 175.2 | S27: Household goods and services | T27: 146.4 | U27: 154.7 | V27: =(U27-T27)/T27 -> 0.056693989
J28: Recreation and amusement | K28: 125.7 | L28: 131.8 | M28: 139.2 | N28: 143.575 | O28: 155.8 | P28: 165.1 | Q28: 171.2 | S28: Recreation and amusement | T28: 143.575 | U28: 155.8 | V28: =(U28-T28)/T28 -> 0.085147136
